<robot name = "my_robot" xmlns:xacro= "http://www.ros.org/wiki/xacro">

    <xacro:property name  = "effort" value = "10000"/>
    <xacro:property name  = "velocity" value = "1000"/>

    <!-- Material Color -->
    <material name="blood" >
        <color rgba="0.4666666666666667 0.0 0.00392156862745098 1.0" />
    </material>
    <material name="berry" >
        <color rgba="0.6 0.058823529411764705 0.29411764705882354 1.0" />
    </material>
    <material name="blueviolet" >
        <color rgba="0.36470588235294116 0.023529411764705882 0.9137254901960784 1.0" />
    </material>
    <material name="bluegrey" >
        <color rgba="0.5215686274509804 0.6392156862745098 0.6980392156862745 1.0" />
    </material>

    <!-- JOINTS -->
    <joint name = "robot_footprint_joint" type = "fixed">
        <origin xyz="0 0 0" rpy = "0 0 0"/>
        <parent link="robot_footprint"/>
        <child link="chassis"/>
    </joint>

    <joint name = "right_wheel_hinge" type = "continuous">
        <origin xyz = "0 0.15 0" rpy = "0 0 0"/>
        <parent link  = "chassis"/>
        <axis xyz="0.0 1.0 0.0"/>
        <child  link = "right_wheel" />
        <limit  effort = "${effort}" velocity = "${velocity}"/>
        <dynamics damping="1.0" friction="1.0"/>
    </joint>
    
    <joint name = "left_wheel_hinge" type = "continuous">
        <origin xyz = "0 -0.15 0" rpy = "0 0 0"/>
        <axis xyz="0.0 1.0 0.0"/>
        <parent link  = "chassis"/>
        <child  link = "left_wheel" />
        <limit  effort = "${effort}" velocity = "${velocity}"/>
        <dynamics damping="1.0" friction="1.0"/>
    </joint>

    <joint name = "Camera_joint" type = "fixed">
        <origin xyz = "0.2 0 0" rpy = "0 0 0"/>
        <parent link = "chassis"/>
        <child  link = "camera"/>
    </joint>

    <joint name = "hokuyo_joint" type  = "fixed">
        <origin xyz = "0.15 0 0.1" rpy = "0 0 0"/>
        <axis   xyz = "0 1 0"/>
        <parent link = "chassis"/>
        <child  link = "hokuyo"/>
    </joint>

    <xacro:include filename = "$(find my_robot)/urdf/my_robot.gazebo"/>

    <!-- LINKS -->    
    <link name = "robot_footprint"></link>

    <link name = "chassis">
        <pose>0 0 0.1 0 0 0</pose>
        <inertial>
            <mass   value = "15.0"/>
            <origin xyz="0.0 0.0 0.0" rpy = "0 0 0"/>
            <inertia ixx="0.1" ixy="0.0" ixz="0.0" 
                     iyy="0.1" iyz="0.0" 
                     izz="0.1"/>
        </inertial>

        <visual name = "chassis_visual">
            <origin xyz="0 0 0" rpy="0 0 0"/>
            <geometry>
                <box size=".4 .2 .1"/>
            </geometry>
            <material name="blueviolet"/>

        </visual>

        <collision name = "chassis_collision">
            <origin xyz="0 0 0" rpy="0 0 0"/>
            <geometry>
                <box size=".4 .2 .1"/>
            </geometry>
        </collision>


        <collision name = "back_caster_collision">
            <origin xyz="-0.15 0.0 -0.05" rpy = "0 0 0"/>
            <geometry>
                <sphere radius="0.0499"/>
            </geometry>
        </collision>

        <visual name = "back_caster_visual">
            <origin xyz="-0.15 0.0 -0.05" rpy = "0 0 0"/>
            <geometry>
                <sphere radius="0.05"/>
            </geometry>
            <material name="berry"/>
        </visual>

        <collision name = "front_caster_collision">
            <origin xyz = "0.15 0 -0.05" rpy = "0 0 0"/>
            <geometry>
                <sphere radius = "0.0499" length  = "0.05"/>
            </geometry>
        </collision>
        
        <visual name = "front_caster_visual">
            <origin xyz = "0.15 0 -0.05" rpy = "0 0 0"/>
            <geometry>
                <sphere radius = "0.05" length  = "0.05"/>
            </geometry>
            <material name="berry"/>
        </visual>
    </link>

    <link name = "right_wheel">
        <visual name = "right_wheel_visual">
            <origin xyz = "0 0 0" rpy = "0 1.5707 1.5707"/>
            <geometry>
                <cylinder radius = "0.1" length  = "0.05"/>
            </geometry> 
            <material name="bluegrey"/>
        </visual>

        <collision name = "right_wheel_collision">
            <origin xyz = "0 0 0" rpy = "0 1.5707 1.5707"/>
            <geometry>
                <cylinder radius = "0.1" length  = "0.05"/>
            </geometry> 
        </collision>
        <inertial>
            <mass value = "5"/>
            <inertia ixx="0.1" ixy="0" ixz="0" iyy="0.1" iyz="0" izz="0.1" />
        </inertial>
    </link>

    <link name = "left_wheel">
        <visual name  = "left_wheel_visual">
            <origin xyz = "0 0 0" rpy = "0 1.5707 1.5707"/>
            <geometry>
                <cylinder radius = "0.1" length  = "0.05"/>
            </geometry>
            <material name="bluegrey"/> 
        </visual>

        <collision name = "left_wheel_collision">
            <origin xyz = "0 0 0" rpy = "0 1.5707 1.5707"/>
            <geometry>
                <cylinder radius = "0.1" length  = "0.05"/>
            </geometry> 
        </collision>
        <inertial>
            <mass value = "5"/>
            <inertia ixx="0.1" ixy="0" ixz="0" iyy="0.1" iyz="0" izz="0.1" />
        </inertial>
    </link>

    <link name = "camera">
        <visual>
            <origin xyz = "0 0 0" rpy = "0 0 0"/>
            <geometry>
                <box size = "0.05 0.05 0.05"/>
            </geometry>
            <material name="blood"/>
        </visual>
        <collision>
            <origin xyz = "0 0 0" rpy = "0 0 0"/>
            <geometry>
                <box size = "0.05 0.05 0.05"/>
            </geometry>
        </collision>
        <inertial>
            <mass value  = "0.1"/>
            <inertia ixx="1e-6" ixy="0" ixz="0" iyy="1e-6" iyz="0" izz="1e-6"/>
        </inertial>
    </link>

    <link name = "hokuyo">
        <visual>
            <origin xyz="0.0 0.0 0.0" rpy="0.0 0.0 0.0" />           
            <geometry>
                <mesh filename="package://my_robot/meshes/hokuyo.dae" />
            </geometry>
        </visual>

        <collision>
            <origin xyz="0.0 0.0 0.0" rpy="0.0 0.0 0.0" />           
            <geometry>
                <box size = "0.1 0.1 0.1"/>
            </geometry>
        </collision>
        <inertial>
            <mass value = "1e-5"/>
            <inertia ixx="1e-6" ixy="0" ixz="0" iyy="1e-6" iyz="0" izz="1e-6" />
        </inertial>
    </link>

</robot>
